<?xml version="1.0" ?>
<!-- =================================================================================== -->
<!-- |    This document was autogenerated by xacro from robo_two_arms_realsense.xacro  | -->
<!-- |    EDITING THIS FILE BY HAND IS NOT RECOMMENDED                                 | -->
<!-- =================================================================================== -->
<robot name="robo_hand" xmlns:xacro="http://ros.org/wiki/xacro">
  <!-- Define a number of dimensions using properties -->
  <!--property name="arm_offset_x" value="-0.143" /-->
  <!--property name="arm_offset_y" value="-0.032" /-->
  <!--property name="arm_offset_z" value="1.302" /-->
  <!-- Include all component files -->
  <!-- Materials -->
  <material name="red">
    <color rgba="1.0 0.0 0.0 0.8"/>
  </material>
  <material name="orange">
    <color rgba="1.0 0.5 0.0 0.8"/>
  </material>
  <material name="yellow">
    <color rgba="1.0 1.0 0.0 0.8"/>
  </material>
  <material name="green">
    <color rgba="0.0 1.0 0.0 0.8"/>
  </material>
  <material name="blue">
    <color rgba="0.0 0.0 1.0 0.8"/>
  </material>
  <material name="indigo">
    <color rgba="0.294 0.0 0.510 0.8"/>
  </material>
  <material name="violet">
    <color rgba="0.561 0.0 1.0 0.8"/>
  </material>
  <material name="realsensecolor">
    <color rgba="0.141 0.529 0.757 0.8"/>
  </material>
  <material name="Black">
    <color rgba="0.2 0.2 0.2 1.0"/>
  </material>
  <material name="TransparentBlack">
    <color rgba="0.2 0.2 0.2 0.8"/>
  </material>
  <material name="Orange">
    <color rgba="1.0  0.55 0.0 1.0"/>
  </material>
  <material name="Grey">
    <color rgba="0.7 0.7 0.7 1.0"/>
  </material>
  <material name="DarkGrey">
    <color rgba="0.3 0.3 0.3 1.0"/>
  </material>
  <material name="Red">
    <color rgba="0.8 0.0 0.0 1.0"/>
  </material>
  <material name="White">
    <color rgba="1.0 1.0 1.0 1.0"/>
  </material>
  <material name="OffWhite">
    <color rgba="0.8 0.8 0.8 1.0"/>
  </material>
  <material name="Blue">
    <color rgba="0.0 0.0 0.8 1.0"/>
  </material>
  <material name="Green">
    <color rgba="0.0 0.8 0.0 1.0"/>
  </material>
  <material name="TransparentGreen">
    <color rgba="0.0 0.8 0.0 0.5"/>
  </material>
  <!-- Variables  -->
  <!-- The base xacro macro -->
  <!-- Define a number of dimensions using properties -->
  <!-- Define the torso -->
  <!-- Now we can start using the macros included above to define the actual robot -->
  <!-- Add the base and wheels -->
  <link name="base_link">
    <visual>
      <origin rpy="0 0 0" xyz="0 0 0"/>
      <geometry>
        <mesh filename="package://robo_description/meshes/base/vis/vis_basewheels_03.STL" scale="0.001 0.001 0.001"/>
      </geometry>
      <material name="orange"/>
    </visual>
    <collision>
      <origin rpy="0 0 0" xyz="0 0 0"/>
      <geometry>
        <mesh filename="package://robo_description/meshes/base/col/col_basewheels_03.STL" scale="0.001 0.001 0.001"/>
      </geometry>
    </collision>
  </link>
  <link name="base_footprint">
    <visual>
      <origin rpy="0 0 0" xyz="0 0 0"/>
      <geometry>
        <box size="0.05 0.05 0.001"/>
      </geometry>
      <material name="TransparentGreen"/>
    </visual>
  </link>
  <joint name="base_joint" type="fixed">
    <origin rpy="0 0 0" xyz="0.0 0.0 0.0"/>
    <parent link="base_footprint"/>
    <child link="base_link"/>
  </joint>
  <!-- Attach the torso -->
  <joint name="base_torso_joint" type="fixed">
    <origin rpy="0 0 0" xyz="0.0 -0.026 1.255"/>
    <parent link="base_link"/>
    <child link="torso_link"/>
  </joint>
  <link name="torso_link">
    <visual>
      <origin rpy="0 0 0" xyz="0 0 0"/>
      <geometry>
        <mesh filename="package://robo_description/meshes/torso/vis/vis_torso_03.STL" scale="0.001 0.001 0.001"/>
      </geometry>
      <material name="red"/>
    </visual>
    <collision>
      <origin rpy="0 0 0" xyz="0 0 0"/>
      <geometry>
        <mesh filename="package://robo_description/meshes/torso/col/col_torso_03.STL" scale="0.001 0.001 0.001"/>
      </geometry>
    </collision>
  </link>
  <!-- Attach the camera -->
  <!-- Telescoping neck joint/link -->
  <joint name="torso_head_tele_joint" type="prismatic">
    <origin rpy="0 0 3.14159" xyz="0.0 0.0 0.0"/>
    <parent link="torso_link"/>
    <child link="head_tele_link"/>
    <axis xyz="0 0 1"/>
    <origin rpy="0 0 0" xyz="0 0 0"/>
    <limit effort="1.0" lower="-0.15" upper="0.15" velocity="0.1"/>
  </joint>
  <link name="head_tele_link">
    <visual>
      <origin rpy="0 0 0" xyz="0 0 0"/>
      <geometry>
        <box size="0.02 0.02 0.5"/>
        <!--mesh filename="package://robo_description/meshes/camera/vis/vis_camera_03.STL" scale="${scale} ${scale} ${scale}" /-->
      </geometry>
      <material name="yellow"/>
    </visual>
    <collision>
      <origin rpy="0 0 0" xyz="0 0 0"/>
      <geometry>
        <box size="0.02 0.02 0.5"/>
        <!--mesh filename="package://robo_description/meshes/camera/col/col_camera_03.STL" scale="${scale} ${scale} ${scale}" /-->
      </geometry>
    </collision>
  </link>
  <!-- Pan joint/link -->
  <joint name="head_pan_joint" type="revolute">
    <axis xyz="0 0 1"/>
    <origin rpy="0 0 0" xyz="0 0 0"/>
    <limit effort="1000.0" lower="-1.570795" upper="1.570795" velocity="0.5"/>
    <parent link="head_tele_link"/>
    <child link="head_pan_link"/>
  </joint>
  <link name="head_pan_link">
    <visual>
      <origin rpy="0 0 0" xyz="0 0 0"/>
      <geometry>
        <box size="0.1 0.1 0.02"/>
      </geometry>
      <material name="blue"/>
    </visual>
    <collision>
      <origin rpy="0 0 0" xyz="0 0 0"/>
      <geometry>
        <box size="0.1 0.1 0.02"/>
      </geometry>
    </collision>
  </link>
  <!-- Tilt joint/link -->
  <joint name="head_tilt_joint" type="revolute">
    <axis xyz="1 0 0"/>
    <origin rpy="0 0 0" xyz="0 0 0"/>
    <limit effort="1000.0" lower="-0.7853975" upper="0.7853975" velocity="0.5"/>
    <parent link="head_pan_link"/>
    <child link="head_tilt_link"/>
  </joint>
  <link name="head_tilt_link">
    <visual>
      <origin rpy="0 0 0" xyz="0 0 0"/>
      <geometry>
        <box size="0.02 0.1 0.1"/>
      </geometry>
      <material name="green"/>
    </visual>
    <collision>
      <origin rpy="0 0 0" xyz="0 0 0"/>
      <geometry>
        <box size="0.02 0.1 0.1"/>
      </geometry>
    </collision>
  </link>
  <!-- Realsense joint/link -->
  <joint name="head_realsense_joint" type="fixed">
    <origin rpy="0 0 3.14159" xyz="0.0 0.0 0.0"/>
    <parent link="head_tilt_link"/>
    <child link="realsense_frame"/>
  </joint>
  <link name="realsense_frame">
    <visual>
      <origin rpy="0 0 0" xyz="0 0 0"/>
      <geometry>
        <mesh filename="package://robo_description/meshes/camera/vis/vis_camera_03.STL" scale="0.001 0.001 0.001"/>
      </geometry>
      <material name="yellow"/>
    </visual>
    <collision>
      <origin rpy="0 0 0" xyz="0 0 0"/>
      <geometry>
        <!--box size="0.1 0.02 0.02"/-->
        <mesh filename="package://robo_description/meshes/camera/col/col_camera_03.STL" scale="0.001 0.001 0.001"/>
      </geometry>
    </collision>
  </link>
  <!-- camera_depth_optical_frame -->
  <joint name="head_depth_joint" type="fixed">
    <origin rpy="0 0 0" xyz="0 0.0 0.268"/>
    <parent link="realsense_frame"/>
    <child link="camera_depth_optical_frame"/>
  </joint>
  <link name="camera_depth_optical_frame">
    <inertial>
      <mass value="0.000001"/>
      <origin xyz="0 0 0"/>
      <inertia ixx="0.0001" ixy="0.0" ixz="0.0" iyy="0.0001" iyz="0.0" izz="0.0001"/>
    </inertial>
  </link>
  <!-- camera_color_optical_frame -->
  <joint name="head_rgb_joint" type="fixed">
    <origin rpy="0 0 0" xyz="0.05 0 0.268"/>
    <parent link="realsense_frame"/>
    <child link="camera_color_optical_frame"/>
  </joint>
  <link name="camera_color_optical_frame">
    <inertial>
      <mass value="0.000001"/>
      <origin xyz="0 0 0"/>
      <inertia ixx="0.0001" ixy="0.0" ixz="0.0" iyy="0.0001" iyz="0.0" izz="0.0001"/>
    </inertial>
  </link>
  <!-- Attach the right arm -->
  <!-- arm base joint -->
  <link name="right_arm_base_link"/>
  <joint name="right_arm_base_joint" type="fixed">
    <origin rpy="0 0 0" xyz="-0.143 0.0055 0.047"/>
    <parent link="torso_link"/>
    <child link="right_arm_base_link"/>
  </joint>
  <!-- Shoulder_A -->
  <link name="right_arm_shouldera_link">
    <visual>
      <origin rpy="0 0 0" xyz="0 0 0"/>
      <geometry>
        <mesh filename="package://robo_description/meshes/arm/vis/vis_right_shouldera_03.STL" scale="0.001 0.001 0.001"/>
      </geometry>
      <material name="orange"/>
    </visual>
    <collision>
      <origin rpy="0 0 0" xyz="0 0 0"/>
      <geometry>
        <mesh filename="package://robo_description/meshes/arm/col/col_right_shouldera_03.STL" scale="0.001 0.001 0.001"/>
      </geometry>
    </collision>
  </link>
  <joint name="right_arm_out_joint" type="revolute">
    <axis xyz="0 1.0 0"/>
    <origin rpy="0 0 0" xyz="0 0 0"/>
    <limit effort="1000.0" lower="0.0" upper="1.5707963" velocity="0.5"/>
    <parent link="right_arm_base_link"/>
    <child link="right_arm_shouldera_link"/>
  </joint>
  <!-- Shoulder_B -->
  <link name="right_arm_shoulderb_link">
    <visual>
      <origin rpy="0 0 0" xyz="0 0 0"/>
      <geometry>
        <mesh filename="package://robo_description/meshes/arm/vis/vis_right_shoulderb_03.STL" scale="0.001 0.001 0.001"/>
      </geometry>
      <material name="yellow"/>
    </visual>
    <collision>
      <origin rpy="0 0 0" xyz="0 0 0"/>
      <geometry>
        <mesh filename="package://robo_description/meshes/arm/col/col_right_shoulderb_03.STL" scale="0.001 0.001 0.001"/>
      </geometry>
    </collision>
  </link>
  <joint name="right_arm_fwd_joint" type="revolute">
    <axis xyz="-1 0 0"/>
    <origin rpy="0 0 0" xyz="-0.012 0.005 -0.04"/>
    <limit effort="1000.0" lower="0.0" upper="1.570795" velocity="0.5"/>
    <parent link="right_arm_shouldera_link"/>
    <child link="right_arm_shoulderb_link"/>
  </joint>
  <!-- Biceps -->
  <link name="right_arm_biceps_link">
    <visual>
      <origin rpy="0 0 0" xyz="0 0 0"/>
      <geometry>
        <mesh filename="package://robo_description/meshes/arm/vis/vis_right_biceps_03.STL" scale="0.001 0.001 0.001"/>
      </geometry>
      <material name="green"/>
    </visual>
    <collision>
      <origin rpy="0 0 0" xyz="0 0 0"/>
      <geometry>
        <mesh filename="package://robo_description/meshes/arm/col/col_right_biceps_03.STL" scale="0.001 0.001 0.001"/>
      </geometry>
    </collision>
  </link>
  <joint name="right_arm_rotate_joint" type="revolute">
    <axis xyz="0 0 -1"/>
    <origin rpy="0 0 0" xyz="-0.06 0 -0.059"/>
    <limit effort="1000.0" lower="-1.570795" upper="1.570795" velocity="0.5"/>
    <parent link="right_arm_shoulderb_link"/>
    <child link="right_arm_biceps_link"/>
  </joint>
  <!-- Forearm -->
  <link name="right_arm_forearm_link">
    <visual>
      <origin rpy="0 0 0" xyz="0 0 0"/>
      <geometry>
        <mesh filename="package://robo_description/meshes/arm/vis/vis_right_forearm_03.STL" scale="0.001 0.001 0.001"/>
      </geometry>
      <material name="blue"/>
    </visual>
    <collision>
      <origin rpy="0 0 0" xyz="0 0 0"/>
      <geometry>
        <mesh filename="package://robo_description/meshes/arm/col/col_right_forearm_03.STL" scale="0.001 0.001 0.001"/>
      </geometry>
    </collision>
  </link>
  <joint name="right_elbow_joint" type="revolute">
    <axis xyz="-1 0 0"/>
    <origin rpy="0 0 0" xyz="0 0.029 -0.225"/>
    <limit effort="1000.0" lower="0.0" upper="1.570795" velocity="0.5"/>
    <parent link="right_arm_biceps_link"/>
    <child link="right_arm_forearm_link"/>
  </joint>
  <!-- Wrist/Hand -->
  <link name="right_arm_wrist_link">
    <visual>
      <origin rpy="0 0 0" xyz="0 0 0"/>
      <geometry>
        <mesh filename="package://robo_description/meshes/arm/vis/vis_right_hand_03.STL" scale="0.001 0.001 0.001"/>
      </geometry>
      <material name="indigo"/>
    </visual>
    <collision>
      <origin rpy="0 0 0" xyz="0 0 0"/>
      <geometry>
        <mesh filename="package://robo_description/meshes/arm/col/col_right_hand_03.STL" scale="0.001 0.001 0.001"/>
      </geometry>
    </collision>
  </link>
  <joint name="right_wrist_joint" type="revolute">
    <axis xyz="0 0 1.0"/>
    <!--origin rpy="0 0 0" xyz=".009972 .012326 -.288718"/-->
    <origin rpy="0 0 0" xyz="0.008 0.01 -0.2888"/>
    <limit effort="1000.0" lower="0.0" upper="3.14159" velocity="0.5"/>
    <parent link="right_arm_forearm_link"/>
    <child link="right_arm_wrist_link"/>
  </joint>
  <!-- Attach the right gripper -->
  <!-- gripper base joint -->
  <link name="right_gripper_base_link"/>
  <joint name="right_gripper_base_joint" type="fixed">
    <origin rpy="0 0 0" xyz="0 0 0"/>
    <parent link="right_arm_wrist_link"/>
    <child link="right_gripper_base_link"/>
  </joint>
  <!-- Index -->
  <link name="right_gripper_index_link">
    <inertial>
      <mass value="0.00001"/>
      <origin xyz="0 0 0"/>
      <inertia ixx="1.0" ixy="0.0" ixz="0.0" iyy="1.0" iyz="0.0" izz="1.0"/>
    </inertial>
    <visual>
      <origin rpy="0 0 0" xyz="0 0 0"/>
      <geometry>
        <mesh filename="package://robo_description/meshes/arm/vis/vis_right_index_03.STL" scale="0.001 0.001 0.001"/>
      </geometry>
      <material name="violet"/>
    </visual>
    <collision>
      <origin rpy="0 0 0" xyz="0 0 0"/>
      <geometry>
        <mesh filename="package://robo_description/meshes/arm/col/col_right_index_03.STL" scale="0.001 0.001 0.001"/>
      </geometry>
    </collision>
  </link>
  <joint name="right_gripper_index_joint" type="revolute">
    <origin rpy="0 0 0" xyz="-0.034 0 -0.119"/>
    <axis xyz="-1 0 0"/>
    <limit effort="1.0" lower="0.0" upper="1.570795" velocity="3.14"/>
    <parent link="right_gripper_base_link"/>
    <child link="right_gripper_index_link"/>
  </joint>
  <!-- Thumb -->
  <link name="right_gripper_thumb_link">
    <inertial>
      <mass value="0.00001"/>
      <origin xyz="0 0 0"/>
      <inertia ixx="1.0" ixy="0.0" ixz="0.0" iyy="1.0" iyz="0.0" izz="1.0"/>
    </inertial>
    <visual>
      <origin rpy="0 0 0" xyz="0 0 0"/>
      <geometry>
        <mesh filename="package://robo_description/meshes/arm/vis/vis_right_thumb_03.STL" scale="0.001 0.001 0.001"/>
      </geometry>
      <material name="violet"/>
    </visual>
    <collision>
      <origin rpy="0 0 0" xyz="0 0 0"/>
      <geometry>
        <mesh filename="package://robo_description/meshes/arm/col/col_right_thumb_03.STL" scale="0.001 0.001 0.001"/>
      </geometry>
    </collision>
  </link>
  <joint name="right_gripper_thumb_joint" type="revolute">
    <origin rpy="0 0 0" xyz="-0.06 0 -0.0685"/>
    <axis xyz="0 0 1.0"/>
    <limit effort="1.0" lower="0.0" upper="1.570795" velocity="3.14"/>
    <parent link="right_gripper_base_link"/>
    <child link="right_gripper_thumb_link"/>
  </joint>
  <!-- Fake gripper link and joint for grasp planning -->
  <link name="right_gripper_link">
    <visual>
      <origin rpy="0 0 0" xyz="0 0 0"/>
      <geometry>
        <box size="0.005 0.005 0.005"/>
      </geometry>
    </visual>
    <collision>
      <origin rpy="0 0 0" xyz="0 0 0"/>
      <geometry>
        <box size="0.005 0.005 0.005"/>
      </geometry>
    </collision>
  </link>
  <joint name="right_gripper_joint" type="fixed">
    <origin rpy="-1.570795 0 0" xyz="0 -0.03 -0.09"/>
    <parent link="right_gripper_base_link"/>
    <child link="right_gripper_link"/>
  </joint>
  <!-- Attach the left arm -->
  <!-- arm base joint -->
  <link name="left_arm_base_link"/>
  <joint name="left_arm_base_joint" type="fixed">
    <origin rpy="0 0 0" xyz="0.143 0.0055 0.047"/>
    <parent link="torso_link"/>
    <child link="left_arm_base_link"/>
  </joint>
  <!-- Shoulder_A -->
  <link name="left_arm_shouldera_link">
    <visual>
      <origin rpy="0 0 0" xyz="0 0 0"/>
      <geometry>
        <mesh filename="package://robo_description/meshes/arm/vis/vis_left_shouldera_03.STL" scale="0.001 0.001 0.001"/>
      </geometry>
      <material name="orange"/>
    </visual>
    <collision>
      <origin rpy="0 0 0" xyz="0 0 0"/>
      <geometry>
        <mesh filename="package://robo_description/meshes/arm/col/col_left_shouldera_03.STL" scale="0.001 0.001 0.001"/>
      </geometry>
    </collision>
  </link>
  <joint name="left_arm_out_joint" type="revolute">
    <axis xyz="0 -1.0 0"/>
    <origin rpy="0 0 0" xyz="0 0 0"/>
    <limit effort="1000.0" lower="0.0" upper="1.5707963" velocity="0.5"/>
    <parent link="left_arm_base_link"/>
    <child link="left_arm_shouldera_link"/>
  </joint>
  <!-- Shoulder_B -->
  <link name="left_arm_shoulderb_link">
    <visual>
      <origin rpy="0 0 0" xyz="0 0 0"/>
      <geometry>
        <mesh filename="package://robo_description/meshes/arm/vis/vis_left_shoulderb_03.STL" scale="0.001 0.001 0.001"/>
      </geometry>
      <material name="yellow"/>
    </visual>
    <collision>
      <origin rpy="0 0 0" xyz="0 0 0"/>
      <geometry>
        <mesh filename="package://robo_description/meshes/arm/col/col_left_shoulderb_03.STL" scale="0.001 0.001 0.001"/>
      </geometry>
    </collision>
  </link>
  <joint name="left_arm_fwd_joint" type="revolute">
    <axis xyz="-1 0 0"/>
    <origin rpy="0 0 0" xyz="0.012 0.005 -0.04"/>
    <limit effort="1000.0" lower="0.0" upper="1.570795" velocity="0.5"/>
    <parent link="left_arm_shouldera_link"/>
    <child link="left_arm_shoulderb_link"/>
  </joint>
  <!-- Biceps -->
  <link name="left_arm_biceps_link">
    <visual>
      <origin rpy="0 0 0" xyz="0 0 0"/>
      <geometry>
        <mesh filename="package://robo_description/meshes/arm/vis/vis_left_biceps_03.STL" scale="0.001 0.001 0.001"/>
      </geometry>
      <material name="green"/>
    </visual>
    <collision>
      <origin rpy="0 0 0" xyz="0 0 0"/>
      <geometry>
        <mesh filename="package://robo_description/meshes/arm/col/col_left_biceps_03.STL" scale="0.001 0.001 0.001"/>
      </geometry>
    </collision>
  </link>
  <joint name="left_arm_rotate_joint" type="revolute">
    <axis xyz="0 0 1"/>
    <origin rpy="0 0 0" xyz="0.06 0 -0.059"/>
    <limit effort="1000.0" lower="-1.570795" upper="1.570795" velocity="0.5"/>
    <parent link="left_arm_shoulderb_link"/>
    <child link="left_arm_biceps_link"/>
  </joint>
  <!-- Forearm -->
  <link name="left_arm_forearm_link">
    <visual>
      <origin rpy="0 0 0" xyz="0 0 0"/>
      <geometry>
        <mesh filename="package://robo_description/meshes/arm/vis/vis_left_forearm_03.STL" scale="0.001 0.001 0.001"/>
      </geometry>
      <material name="blue"/>
    </visual>
    <collision>
      <origin rpy="0 0 0" xyz="0 0 0"/>
      <geometry>
        <mesh filename="package://robo_description/meshes/arm/col/col_left_forearm_03.STL" scale="0.001 0.001 0.001"/>
      </geometry>
    </collision>
  </link>
  <joint name="left_elbow_joint" type="revolute">
    <axis xyz="-1 0 0"/>
    <origin rpy="0 0 0" xyz="0 0.029 -0.225"/>
    <limit effort="1000.0" lower="0.0" upper="1.570795" velocity="0.5"/>
    <parent link="left_arm_biceps_link"/>
    <child link="left_arm_forearm_link"/>
  </joint>
  <!-- Wrist/Hand -->
  <link name="left_arm_wrist_link">
    <visual>
      <origin rpy="0 0 0" xyz="0 0 0"/>
      <geometry>
        <mesh filename="package://robo_description/meshes/arm/vis/vis_left_hand_03.STL" scale="0.001 0.001 0.001"/>
      </geometry>
      <material name="indigo"/>
    </visual>
    <collision>
      <origin rpy="0 0 0" xyz="0 0 0"/>
      <geometry>
        <mesh filename="package://robo_description/meshes/arm/col/col_left_hand_03.STL" scale="0.001 0.001 0.001"/>
      </geometry>
    </collision>
  </link>
  <joint name="left_wrist_joint" type="revolute">
    <axis xyz="0 0 -1.0"/>
    <!--origin rpy="0 0 0" xyz=".009972 .012326 -.288718"/-->
    <origin rpy="0 0 0" xyz="0.008 -0.01 -0.2888"/>
    <limit effort="1000.0" lower="0.0" upper="3.14159" velocity="0.5"/>
    <parent link="left_arm_forearm_link"/>
    <child link="left_arm_wrist_link"/>
  </joint>
  <!-- Attach the left gripper -->
  <!-- gripper base joint -->
  <link name="left_gripper_base_link"/>
  <joint name="left_gripper_base_joint" type="fixed">
    <origin rpy="0 0 0" xyz="0 0 0"/>
    <parent link="left_arm_wrist_link"/>
    <child link="left_gripper_base_link"/>
  </joint>
  <!-- Index -->
  <link name="left_gripper_index_link">
    <inertial>
      <mass value="0.00001"/>
      <origin xyz="0 0 0"/>
      <inertia ixx="1.0" ixy="0.0" ixz="0.0" iyy="1.0" iyz="0.0" izz="1.0"/>
    </inertial>
    <visual>
      <origin rpy="0 0 0" xyz="0 0 0"/>
      <geometry>
        <mesh filename="package://robo_description/meshes/arm/vis/vis_left_index_03.STL" scale="0.001 0.001 0.001"/>
      </geometry>
      <material name="violet"/>
    </visual>
    <collision>
      <origin rpy="0 0 0" xyz="0 0 0"/>
      <geometry>
        <mesh filename="package://robo_description/meshes/arm/col/col_left_index_03.STL" scale="0.001 0.001 0.001"/>
      </geometry>
    </collision>
  </link>
  <joint name="left_gripper_index_joint" type="revolute">
    <origin rpy="0 0 0" xyz="0.034 0 -0.119"/>
    <axis xyz="-1 0 0"/>
    <limit effort="1.0" lower="0.0" upper="1.570795" velocity="3.14"/>
    <parent link="left_gripper_base_link"/>
    <child link="left_gripper_index_link"/>
  </joint>
  <!-- Thumb -->
  <link name="left_gripper_thumb_link">
    <inertial>
      <mass value="0.00001"/>
      <origin xyz="0 0 0"/>
      <inertia ixx="1.0" ixy="0.0" ixz="0.0" iyy="1.0" iyz="0.0" izz="1.0"/>
    </inertial>
    <visual>
      <origin rpy="0 0 0" xyz="0 0 0"/>
      <geometry>
        <mesh filename="package://robo_description/meshes/arm/vis/vis_left_thumb_03.STL" scale="0.001 0.001 0.001"/>
      </geometry>
      <material name="violet"/>
    </visual>
    <collision>
      <origin rpy="0 0 0" xyz="0 0 0"/>
      <geometry>
        <mesh filename="package://robo_description/meshes/arm/col/col_left_thumb_03.STL" scale="0.001 0.001 0.001"/>
      </geometry>
    </collision>
  </link>
  <joint name="left_gripper_thumb_joint" type="revolute">
    <origin rpy="0 0 0" xyz="0.06 0 -0.0685"/>
    <axis xyz="0 0 -1.0"/>
    <limit effort="1.0" lower="0.0" upper="1.570795" velocity="3.14"/>
    <parent link="left_gripper_base_link"/>
    <child link="left_gripper_thumb_link"/>
  </joint>
  <!-- Fake gripper link and joint for grasp planning -->
  <link name="left_gripper_link">
    <visual>
      <origin rpy="0 0 0" xyz="0 0 0"/>
      <geometry>
        <box size="0.005 0.005 0.005"/>
      </geometry>
    </visual>
    <collision>
      <origin rpy="0 0 0" xyz="0 0 0"/>
      <geometry>
        <box size="0.005 0.005 0.005"/>
      </geometry>
    </collision>
  </link>
  <joint name="left_gripper_joint" type="fixed">
    <origin rpy="-1.570795 0 0" xyz="0 -0.03 -0.09"/>
    <parent link="left_gripper_base_link"/>
    <child link="left_gripper_link"/>
  </joint>
</robot>

