<?xml version="1.0" ?>
<!-- =================================================================================== -->
<!-- |    This document was autogenerated by xacro from robo_two_arms_realsense.xacro  | -->
<!-- |    EDITING THIS FILE BY HAND IS NOT RECOMMENDED                                 | -->
<!-- =================================================================================== -->
<robot name="robo_hand" xmlns:xacro="http://ros.org/wiki/xacro">
  <!-- Properties -->
  <!-- Include files -->
  <!-- Materials -->
  <material name="red">
    <color rgba="1.0 0.0 0.0 0.8"/>
  </material>
  <material name="orange">
    <color rgba="1.0 0.5 0.0 0.8"/>
  </material>
  <material name="yellow">
    <color rgba="1.0 1.0 0.0 0.8"/>
  </material>
  <material name="green">
    <color rgba="0.0 1.0 0.0 0.8"/>
  </material>
  <material name="blue">
    <color rgba="0.0 0.0 1.0 0.8"/>
  </material>
  <material name="indigo">
    <color rgba="0.294 0.0 0.510 0.8"/>
  </material>
  <material name="violet">
    <color rgba="0.561 0.0 1.0 0.8"/>
  </material>
  <material name="realsensecolor">
    <color rgba="0.141 0.529 0.757 0.8"/>
  </material>
  <material name="Black">
    <color rgba="0.2 0.2 0.2 1.0"/>
  </material>
  <material name="TransparentBlack">
    <color rgba="0.2 0.2 0.2 0.8"/>
  </material>
  <material name="Orange">
    <color rgba="1.0  0.55 0.0 1.0"/>
  </material>
  <material name="Grey">
    <color rgba="0.7 0.7 0.7 1.0"/>
  </material>
  <material name="DarkGrey">
    <color rgba="0.3 0.3 0.3 1.0"/>
  </material>
  <material name="Red">
    <color rgba="0.8 0.0 0.0 1.0"/>
  </material>
  <material name="White">
    <color rgba="1.0 1.0 1.0 1.0"/>
  </material>
  <material name="OffWhite">
    <color rgba="0.8 0.8 0.8 1.0"/>
  </material>
  <material name="Blue">
    <color rgba="0.0 0.0 0.8 1.0"/>
  </material>
  <material name="Green">
    <color rgba="0.0 0.8 0.0 1.0"/>
  </material>
  <material name="TransparentGreen">
    <color rgba="0.0 0.8 0.0 0.5"/>
  </material>
  <!-- Properties  -->
  <!-- Macro -->
  <!-- Properties -->
  <!-- Macro -->
  <!-- Properties -->
  <!-- Macro -->
  <!-- Properties -->
  <!-- Macro -->
  <!-- Properties -->
  <!-- Macro -->
  <!-- Components -->
  <!-- Base -->
  <!-- L -->
  <link name="base_footprint">
    <visual>
      <origin rpy="0 0 0" xyz="0 0 0"/>
      <geometry>
        <box size="0.05 0.05 0.001"/>
      </geometry>
      <material name="TransparentGreen"/>
    </visual>
  </link>
  <!-- J -->
  <joint name="base_joint" type="fixed">
    <!--xacro:insert_block name="origin"/-->
    <origin rpy="0 0 0" xyz="0.0 0.0 0.0"/>
    <parent link="base_footprint"/>
    <child link="base_link"/>
  </joint>
  <!-- L -->
  <link name="base_link">
    <visual>
      <origin rpy="0 0 3.14159" xyz="0 0 0"/>
      <geometry>
        <mesh filename="package://robo_description/meshes/base/vis/vis_basewheels_03.STL" scale="0.001 0.001 0.001"/>
      </geometry>
      <material name="orange"/>
    </visual>
    <collision>
      <origin rpy="0 0 3.14159" xyz="0 0 0"/>
      <geometry>
        <mesh filename="package://robo_description/meshes/base/col/col_basewheels_03.STL" scale="0.001 0.001 0.001"/>
      </geometry>
    </collision>
  </link>
  <!-- Torso -->
  <!-- J -->
  <joint name="base_torso_joint" type="fixed">
    <origin rpy="0 0 0" xyz="0.0 -0.02 1.255"/>
    <origin rpy="0 0 0" xyz="0 0 0"/>
    <parent link="base_link"/>
    <child link="torso_link"/>
  </joint>
  <!-- L -->
  <link name="torso_link">
    <visual>
      <origin rpy="0 0 3.14159" xyz="0 0 0"/>
      <geometry>
        <mesh filename="package://robo_description/meshes/torso/vis/vis_torso_03.STL" scale="0.001 0.001 0.001"/>
      </geometry>
      <material name="red"/>
    </visual>
    <collision>
      <origin rpy="0 0 0" xyz="0 0 0"/>
      <geometry>
        <mesh filename="package://robo_description/meshes/torso/col/col_torso_03.STL" scale="0.001 0.001 0.001"/>
      </geometry>
    </collision>
  </link>
  <!-- J -->
  <joint name="head_col_joint" type="fixed">
    <origin rpy="0 0 0" xyz="0 0 0.24"/>
    <parent link="torso_link"/>
    <child link="head_col_link"/>
  </joint>
  <!-- L -->
  <link name="head_col_link">
    <visual>
      <origin rpy="0 0 0" xyz="0 0 0"/>
      <geometry>
        <box size="0.01 0.01 0.01"/>
      </geometry>
    </visual>
    <collision>
      <origin rpy="0 0 0" xyz="0 0 0"/>
      <geometry>
        <box size="0.15 0.15 0.25"/>
      </geometry>
    </collision>
  </link>
  <!-- Head/camera -->
  <!-- Telescoping neck -->
  <!-- J -->
  <joint name="torso_head_tele_joint" type="prismatic">
    <origin rpy="0 0 0" xyz="0.0 0.0 0.0"/>
    <parent link="torso_link"/>
    <child link="head_tele_link"/>
    <axis xyz="0 0 1"/>
    <limit effort="1.0" lower="0" upper="0.19" velocity="0.1"/>
  </joint>
  <!-- L -->
  <link name="head_tele_link">
    <visual>
      <origin rpy="0 0 0" xyz="0 0 0"/>
      <geometry>
        <box size="0.01 0.01 0.25"/>
      </geometry>
      <material name="yellow"/>
    </visual>
    <!--collision>
        <origin xyz="0 0 0" rpy="0 0 0"/>
        <geometry>
          <box size="0.02 0.02 0.5"/>
        </geometry>
      </collision!-->
  </link>
  <!-- Neck to pan fixed -->
  <!-- J -->
  <joint name="head_neck_joint" type="fixed">
    <origin rpy="0 0 0" xyz="0 0 0.135"/>
    <parent link="head_tele_link"/>
    <child link="head_neck_link"/>
  </joint>
  <!-- L -->
  <!-- This contains the head collision box -->
  <link name="head_neck_link">
    <visual>
      <origin rpy="0 0 0" xyz="0 0 0"/>
      <geometry>
        <box size="0.01 0.03 0.03"/>
      </geometry>
      <material name="green"/>
    </visual>
    <!--collision>
        <origin xyz="0 0 0.1" rpy="0 0 0"/>
        <geometry>
          <box size="0.2 0.2 0.2"/>
        </geometry>
      </collision!-->
  </link>
  <!-- Pan -->
  <!-- J  -->
  <joint name="head_pan_joint" type="revolute">
    <axis xyz="0 0 -1"/>
    <origin rpy="0 0 0" xyz="0 0 0.02"/>
    <limit effort="1000.0" lower="-1.570795" upper="1.570795" velocity="0.5"/>
    <parent link="head_neck_link"/>
    <child link="head_pan_link"/>
  </joint>
  <!-- L -->
  <link name="head_pan_link">
    <visual>
      <origin rpy="0 0 0" xyz="0 0 0"/>
      <geometry>
        <box size="0.03 0.03 0.01"/>
      </geometry>
      <material name="blue"/>
    </visual>
    <!--collision>
        <origin xyz="0 0 0" rpy="0 0 0"/>
        <geometry>
          <box size="0.03 0.03 0.01"/>
        </geometry>
      </collision!-->
  </link>
  <!-- Tilt -->
  <!-- J -->
  <joint name="head_tilt_joint" type="revolute">
    <axis xyz="1 0 0"/>
    <origin rpy="0 0 0" xyz="0 0.01 0"/>
    <limit effort="1000.0" lower="-0.7853975" upper="1.884954" velocity="0.5"/>
    <parent link="head_pan_link"/>
    <child link="head_tilt_link"/>
  </joint>
  <!-- L -->
  <link name="head_tilt_link">
    <visual>
      <origin rpy="0 0 0" xyz="0 0.01 0"/>
      <geometry>
        <box size="0.035 0.025 0.01"/>
      </geometry>
      <material name="indigo"/>
    </visual>
    <!--collision>
        <origin xyz="0 0.01 0" rpy="0 0 0"/>
        <geometry>
          <box size="0.035 0.025 0.01"/>
        </geometry>
      </collision!-->
  </link>
  <!-- Realsense body -->
  <!-- J -->
  <joint name="head_realsense_joint" type="fixed">
    <origin rpy="0 0 0" xyz="0.0 0.0 0.0"/>
    <parent link="head_tilt_link"/>
    <child link="realsense_link"/>
  </joint>
  <!-- L -->
  <link name="realsense_link">
    <visual>
      <origin rpy="0 0 3.14159" xyz="0.01 0.025 -0.01"/>
      <geometry>
        <mesh filename="package://robo_description/meshes/camera/vis/RealSense.STL" scale="0.001 0.001 0.001"/>
      </geometry>
      <material name="realsensecolor"/>
    </visual>
    <!--collision>
        <origin xyz="0.01 0.025 -0.01" rpy="0 0 ${pi}"/>
        <geometry>
          <mesh filename="package://robo_description/meshes/camera/col/col_camera_03.STL" scale="${scale} ${scale} ${scale}"/>
        </geometry>
      </collision!-->
  </link>
  <!-- Head tracker point A -->
  <!-- J -->
  <joint name="head_tracker_A_joint" type="fixed">
    <!--axis xyz="1 1 1"/-->
    <!--limit effort="1000.0" lower="${pi}" upper="${pi}" velocity="0.5"/-->
    <!--origin xyz="0 0 0" rpy="${pi/2} ${pi/2} 0"/-->
    <origin rpy="1.57 1.57 0.0" xyz="0 -0.01 0"/>
    <parent link="realsense_link"/>
    <child link="head_tracker_A_link"/>
  </joint>
  <!-- L -->
  <link name="head_tracker_A_link">
    <visual>
      <origin rpy="0 0 0" xyz="0 0 0"/>
      <geometry>
        <box size="0.01 0.01 0.01"/>
      </geometry>
      <material name="indigo"/>
    </visual>
  </link>
  <!-- Head tracker point B -->
  <!-- J2 -->
  <joint name="head_tracker_B_joint" type="fixed">
    <!--axis xyz="1 1 1"/-->
    <!--limit effort="1000.0" lower="${pi}" upper="${pi}" velocity="0.5"/-->
    <!--origin xyz="0 0 0" rpy="${pi/2} ${pi/2} 0"/-->
    <origin rpy="0.628318 1.57 0.0" xyz="0 0 0"/>
    <parent link="head_tracker_A_link"/>
    <child link="head_tracker_B_link"/>
  </joint>
  <!-- L2 -->
  <link name="head_tracker_B_link">
    <!--visual>
        <origin xyz="0 0 0" rpy="0 0 0"/>
        <geometry>          
          <box size="0.01 0.01 0.01"/>
        </geometry>
        <material name="orange"/>
      </visual-->
  </link>
  <!-- realsense_frame -->
  <!-- J -->
  <joint name="head_realsense_frame_joint" type="fixed">
    <origin rpy="1.570795 3.14159 3.14159" xyz="0.0588 0.027 0.0037"/>
    <parent link="realsense_link"/>
    <child link="realsense_frame"/>
  </joint>
  <!-- L -->
  <link name="realsense_frame">
    <visual>
      <origin rpy="0 0 0" xyz="0 0 0"/>
      <geometry>
        <box size="0.003 0.003 0.0005"/>
      </geometry>
      <material name="violet"/>
    </visual>
  </link>
  <!-- camera_depth_frame -->
  <!-- J -->
  <joint name="head_depth_joint" type="fixed">
    <origin rpy="0 0 0" xyz="0 0 0"/>
    <parent link="realsense_frame"/>
    <child link="camera_depth_optical_frame"/>
  </joint>
  <!-- L -->
  <link name="camera_depth_optical_frame">
    <inertial>
      <mass value="0.000001"/>
      <origin rpy="0 0 0" xyz="0 0 0"/>
      <inertia ixx="0.0001" ixy="0.0" ixz="0.0" iyy="0.0001" iyz="0.0" izz="0.0001"/>
    </inertial>
  </link>
  <!-- camera_color_optical_frame -->
  <!-- J -->
  <joint name="head_rgb_joint" type="fixed">
    <origin rpy="0 0 0" xyz="0 0.0003 0"/>
    <parent link="realsense_frame"/>
    <child link="camera_color_optical_frame"/>
  </joint>
  <!-- L -->
  <link name="camera_color_optical_frame">
    <visual>
      <origin rpy="0 0 0" xyz="0 0 0"/>
      <geometry>
        <box size="0.003 0.003 0.001"/>
      </geometry>
      <material name="violet"/>
    </visual>
    <inertial>
      <mass value="0.000001"/>
      <origin rpy="0 0 0" xyz="0 0 0"/>
      <inertia ixx="0.0001" ixy="0.0" ixz="0.0" iyy="0.0001" iyz="0.0" izz="0.0001"/>
    </inertial>
  </link>
  <!-- Right arm -->
  <!-- Arm base -->
  <!-- L -->
  <link name="right_arm_base_link"/>
  <!-- J -->
  <joint name="right_arm_base_joint" type="fixed">
    <origin rpy="0 0 3.14159" xyz="0.143 0.0055 0.047"/>
    <parent link="torso_link"/>
    <child link="right_arm_base_link"/>
  </joint>
  <!-- Arm out -->
  <!-- J -->
  <joint name="right_arm_out_joint" type="revolute">
    <axis xyz="0 1.0 0"/>
    <origin rpy="0 0 0" xyz="0 0 0"/>
    <origin rpy="0 0 3.14159" xyz="0.143 0.0055 0.047"/>
    <limit effort="1000.0" lower="0.0" upper="1.570795" velocity="0.5"/>
    <parent link="right_arm_base_link"/>
    <child link="right_arm_shouldera_link"/>
  </joint>
  <!-- L -->
  <link name="right_arm_shouldera_link">
    <visual>
      <origin rpy="0 0 0" xyz="0 0 0"/>
      <geometry>
        <mesh filename="package://robo_description/meshes/arm/vis/vis_right_shouldera_03.STL" scale="0.001 0.001 0.001"/>
      </geometry>
      <material name="orange"/>
    </visual>
    <collision>
      <origin rpy="0 0 0" xyz="0 0 0"/>
      <geometry>
        <mesh filename="package://robo_description/meshes/arm/col/col_right_shouldera_03.STL" scale="0.001 0.001 0.001"/>
      </geometry>
    </collision>
  </link>
  <!-- Arm forward -->
  <!-- J -->
  <joint name="right_arm_fwd_joint" type="revolute">
    <axis xyz="-1 0 0"/>
    <origin rpy="0 0 0" xyz="-0.012 0.005 -0.04"/>
    <limit effort="1000.0" lower="-1.570795" upper="1.570795" velocity="0.5"/>
    <parent link="right_arm_shouldera_link"/>
    <child link="right_arm_shoulderb_link"/>
  </joint>
  <!-- L -->
  <link name="right_arm_shoulderb_link">
    <visual>
      <origin rpy="0 0 0" xyz="0 0 0"/>
      <geometry>
        <mesh filename="package://robo_description/meshes/arm/vis/vis_right_shoulderb_03.STL" scale="0.001 0.001 0.001"/>
      </geometry>
      <material name="yellow"/>
    </visual>
    <collision>
      <origin rpy="0 0 0" xyz="0 0 0"/>
      <geometry>
        <mesh filename="package://robo_description/meshes/arm/col/col_right_shoulderb_03.STL" scale="0.001 0.001 0.001"/>
      </geometry>
    </collision>
  </link>
  <!-- Arm rotate -->
  <!-- J -->
  <joint name="right_arm_rotate_joint" type="revolute">
    <axis xyz="0 0 -1"/>
    <origin rpy="0 0 0" xyz="-0.06 0 -0.059"/>
    <limit effort="1000.0" lower="-1.570795" upper="1.570795" velocity="0.5"/>
    <parent link="right_arm_shoulderb_link"/>
    <child link="right_arm_biceps_link"/>
  </joint>
  <!-- L -->
  <link name="right_arm_biceps_link">
    <visual>
      <origin rpy="0 0 0" xyz="0 0 0"/>
      <geometry>
        <mesh filename="package://robo_description/meshes/arm/vis/vis_right_biceps_03.STL" scale="0.001 0.001 0.001"/>
      </geometry>
      <material name="green"/>
    </visual>
    <collision>
      <origin rpy="0 0 0" xyz="0 0 0"/>
      <geometry>
        <mesh filename="package://robo_description/meshes/arm/col/col_right_biceps_03.STL" scale="0.001 0.001 0.001"/>
      </geometry>
    </collision>
  </link>
  <!-- Elbow -->
  <!-- J -->
  <joint name="right_elbow_joint" type="revolute">
    <axis xyz="-1 0 0"/>
    <origin rpy="0 0 0" xyz="0 0.029 -0.225"/>
    <limit effort="1000.0" lower="0.0" upper="1.570795" velocity="0.5"/>
    <parent link="right_arm_biceps_link"/>
    <child link="right_arm_forearm_link"/>
  </joint>
  <!-- L -->
  <link name="right_arm_forearm_link">
    <visual>
      <origin rpy="0 0 0" xyz="0 0 0"/>
      <geometry>
        <mesh filename="package://robo_description/meshes/arm/vis/vis_right_forearm_03.STL" scale="0.001 0.001 0.001"/>
      </geometry>
      <material name="blue"/>
    </visual>
    <collision>
      <origin rpy="0 0 0" xyz="0 0 0"/>
      <geometry>
        <mesh filename="package://robo_description/meshes/arm/col/col_right_forearm_03.STL" scale="0.001 0.001 0.001"/>
      </geometry>
    </collision>
  </link>
  <!-- Wrist/Hand -->
  <!-- J -->
  <joint name="right_wrist_joint" type="revolute">
    <axis xyz="0 0 1.0"/>
    <!--origin rpy="0 0 0" xyz=".009972 .012326 -.288718"/-->
    <origin rpy="0 0 0" xyz="0.008 0.01 -0.2888"/>
    <limit effort="1000.0" lower="0.0" upper="3.14159" velocity="0.5"/>
    <parent link="right_arm_forearm_link"/>
    <child link="right_arm_wrist_link"/>
  </joint>
  <!-- L -->
  <link name="right_arm_wrist_link">
    <visual>
      <origin rpy="0 0 0" xyz="0 0 0"/>
      <geometry>
        <mesh filename="package://robo_description/meshes/arm/vis/vis_right_hand_03.STL" scale="0.001 0.001 0.001"/>
      </geometry>
      <material name="indigo"/>
    </visual>
    <collision>
      <origin rpy="0 0 0" xyz="0 0 0"/>
      <geometry>
        <mesh filename="package://robo_description/meshes/arm/col/col_right_hand_03.STL" scale="0.001 0.001 0.001"/>
      </geometry>
    </collision>
  </link>
  <!-- Right gripper -->
  <!-- gripper base joint -->
  <!-- L -->
  <link name="right_gripper_base_link"/>
  <!-- J -->
  <joint name="right_gripper_base_joint" type="fixed">
    <origin rpy="0 0 0" xyz="0 0 0"/>
    <parent link="right_arm_wrist_link"/>
    <child link="right_gripper_base_link"/>
  </joint>
  <!-- Index -->
  <!-- J -->
  <joint name="right_gripper_index_joint" type="revolute">
    <origin rpy="0 0 0" xyz="-0.034 0 -0.119"/>
    <axis xyz="-1 0 0"/>
    <limit effort="1.0" lower="0.0" upper="1.570795" velocity="3.14"/>
    <parent link="right_gripper_base_link"/>
    <child link="right_gripper_index_link"/>
  </joint>
  <!-- L -->
  <link name="right_gripper_index_link">
    <inertial>
      <mass value="0.00001"/>
      <origin xyz="0 0 0"/>
      <inertia ixx="1.0" ixy="0.0" ixz="0.0" iyy="1.0" iyz="0.0" izz="1.0"/>
    </inertial>
    <visual>
      <origin rpy="0 0 0" xyz="0 0 0"/>
      <geometry>
        <mesh filename="package://robo_description/meshes/arm/vis/vis_right_index_03.STL" scale="0.001 0.001 0.001"/>
      </geometry>
      <material name="violet"/>
    </visual>
    <collision>
      <origin rpy="0 0 0" xyz="0 0 0"/>
      <geometry>
        <mesh filename="package://robo_description/meshes/arm/col/col_right_index_03.STL" scale="0.001 0.001 0.001"/>
      </geometry>
    </collision>
  </link>
  <!-- Thumb -->
  <!-- J -->
  <joint name="right_gripper_thumb_joint" type="revolute">
    <origin rpy="0 0 0" xyz="-0.06 0 -0.0685"/>
    <axis xyz="0 0 1.0"/>
    <limit effort="1.0" lower="0.0" upper="1.570795" velocity="3.14"/>
    <parent link="right_gripper_base_link"/>
    <child link="right_gripper_thumb_link"/>
  </joint>
  <!-- L -->
  <link name="right_gripper_thumb_link">
    <inertial>
      <mass value="0.00001"/>
      <origin xyz="0 0 0"/>
      <inertia ixx="1.0" ixy="0.0" ixz="0.0" iyy="1.0" iyz="0.0" izz="1.0"/>
    </inertial>
    <visual>
      <origin rpy="0 0 0" xyz="0 0 0"/>
      <geometry>
        <mesh filename="package://robo_description/meshes/arm/vis/vis_right_thumb_03.STL" scale="0.001 0.001 0.001"/>
      </geometry>
      <material name="violet"/>
    </visual>
    <collision>
      <origin rpy="0 0 0" xyz="0 0 0"/>
      <geometry>
        <mesh filename="package://robo_description/meshes/arm/col/col_right_thumb_03.STL" scale="0.001 0.001 0.001"/>
      </geometry>
    </collision>
  </link>
  <!-- Fake gripper link and joint for grasp planning -->
  <!-- J -->
  <joint name="right_gripper_joint" type="fixed">
    <origin rpy="-1.570795 0 0" xyz="0 -0.03 -0.09"/>
    <parent link="right_gripper_base_link"/>
    <child link="right_gripper_link"/>
  </joint>
  <!-- L -->
  <link name="right_gripper_link">
    <visual>
      <origin rpy="0 0 0" xyz="0 0 0"/>
      <geometry>
        <box size="0.005 0.005 0.005"/>
      </geometry>
    </visual>
    <collision>
      <origin rpy="0 0 0" xyz="0 0 0"/>
      <geometry>
        <box size="0.005 0.005 0.005"/>
      </geometry>
    </collision>
  </link>
  <!-- Left arm -->
  <!-- Arm base -->
  <!-- L -->
  <link name="left_arm_base_link"/>
  <!-- J -->
  <joint name="left_arm_base_joint" type="fixed">
    <origin rpy="0 0 3.14159" xyz="-0.143 0.0055 0.047"/>
    <parent link="torso_link"/>
    <child link="left_arm_base_link"/>
  </joint>
  <!-- Arm out -->
  <!-- J -->
  <joint name="left_arm_out_joint" type="revolute">
    <axis xyz="0 -1.0 0"/>
    <origin rpy="0 0 0" xyz="0 0 0"/>
    <origin rpy="0 0 3.14159" xyz="-0.143 0.0055 0.047"/>
    <limit effort="1000.0" lower="0.0" upper="1.570795" velocity="0.5"/>
    <parent link="left_arm_base_link"/>
    <child link="left_arm_shouldera_link"/>
  </joint>
  <!-- L -->
  <link name="left_arm_shouldera_link">
    <visual>
      <origin rpy="0 0 0" xyz="0 0 0"/>
      <geometry>
        <mesh filename="package://robo_description/meshes/arm/vis/vis_left_shouldera_03.STL" scale="0.001 0.001 0.001"/>
      </geometry>
      <material name="orange"/>
    </visual>
    <collision>
      <origin rpy="0 0 0" xyz="0 0 0"/>
      <geometry>
        <mesh filename="package://robo_description/meshes/arm/col/col_left_shouldera_03.STL" scale="0.001 0.001 0.001"/>
      </geometry>
    </collision>
  </link>
  <!-- Arm forward -->
  <!-- J -->
  <joint name="left_arm_fwd_joint" type="revolute">
    <axis xyz="-1 0 0"/>
    <origin rpy="0 0 0" xyz="0.012 0.005 -0.04"/>
    <limit effort="1000.0" lower="-1.570795" upper="1.570795" velocity="0.5"/>
    <parent link="left_arm_shouldera_link"/>
    <child link="left_arm_shoulderb_link"/>
  </joint>
  <!-- L -->
  <link name="left_arm_shoulderb_link">
    <visual>
      <origin rpy="0 0 0" xyz="0 0 0"/>
      <geometry>
        <mesh filename="package://robo_description/meshes/arm/vis/vis_left_shoulderb_03.STL" scale="0.001 0.001 0.001"/>
      </geometry>
      <material name="yellow"/>
    </visual>
    <collision>
      <origin rpy="0 0 0" xyz="0 0 0"/>
      <geometry>
        <mesh filename="package://robo_description/meshes/arm/col/col_left_shoulderb_03.STL" scale="0.001 0.001 0.001"/>
      </geometry>
    </collision>
  </link>
  <!-- Arm rotate -->
  <!-- J -->
  <joint name="left_arm_rotate_joint" type="revolute">
    <axis xyz="0 0 1"/>
    <origin rpy="0 0 0" xyz="0.06 0 -0.059"/>
    <limit effort="1000.0" lower="-1.570795" upper="1.570795" velocity="0.5"/>
    <parent link="left_arm_shoulderb_link"/>
    <child link="left_arm_biceps_link"/>
  </joint>
  <!-- L -->
  <link name="left_arm_biceps_link">
    <visual>
      <origin rpy="0 0 0" xyz="0 0 0"/>
      <geometry>
        <mesh filename="package://robo_description/meshes/arm/vis/vis_left_biceps_03.STL" scale="0.001 0.001 0.001"/>
      </geometry>
      <material name="green"/>
    </visual>
    <collision>
      <origin rpy="0 0 0" xyz="0 0 0"/>
      <geometry>
        <mesh filename="package://robo_description/meshes/arm/col/col_left_biceps_03.STL" scale="0.001 0.001 0.001"/>
      </geometry>
    </collision>
  </link>
  <!-- Elbow -->
  <!-- J -->
  <joint name="left_elbow_joint" type="revolute">
    <axis xyz="-1 0 0"/>
    <origin rpy="0 0 0" xyz="0 0.029 -0.225"/>
    <limit effort="1000.0" lower="0.0" upper="1.570795" velocity="0.5"/>
    <parent link="left_arm_biceps_link"/>
    <child link="left_arm_forearm_link"/>
  </joint>
  <!-- L -->
  <link name="left_arm_forearm_link">
    <visual>
      <origin rpy="0 0 0" xyz="0 0 0"/>
      <geometry>
        <mesh filename="package://robo_description/meshes/arm/vis/vis_left_forearm_03.STL" scale="0.001 0.001 0.001"/>
      </geometry>
      <material name="blue"/>
    </visual>
    <collision>
      <origin rpy="0 0 0" xyz="0 0 0"/>
      <geometry>
        <mesh filename="package://robo_description/meshes/arm/col/col_left_forearm_03.STL" scale="0.001 0.001 0.001"/>
      </geometry>
    </collision>
  </link>
  <!-- Wrist/Hand -->
  <!-- J -->
  <joint name="left_wrist_joint" type="revolute">
    <axis xyz="0 0 -1.0"/>
    <!--origin rpy="0 0 0" xyz=".009972 .012326 -.288718"/-->
    <origin rpy="0 0 0" xyz="0.008 -0.01 -0.2888"/>
    <limit effort="1000.0" lower="0.0" upper="3.14159" velocity="0.5"/>
    <parent link="left_arm_forearm_link"/>
    <child link="left_arm_wrist_link"/>
  </joint>
  <!-- L -->
  <link name="left_arm_wrist_link">
    <visual>
      <origin rpy="0 0 0" xyz="0 0 0"/>
      <geometry>
        <mesh filename="package://robo_description/meshes/arm/vis/vis_left_hand_03.STL" scale="0.001 0.001 0.001"/>
      </geometry>
      <material name="indigo"/>
    </visual>
    <collision>
      <origin rpy="0 0 0" xyz="0 0 0"/>
      <geometry>
        <mesh filename="package://robo_description/meshes/arm/col/col_left_hand_03.STL" scale="0.001 0.001 0.001"/>
      </geometry>
    </collision>
  </link>
  <!-- Left gripper -->
  <!-- gripper base joint -->
  <!-- L -->
  <link name="left_gripper_base_link"/>
  <!-- J -->
  <joint name="left_gripper_base_joint" type="fixed">
    <origin rpy="0 0 0" xyz="0 0 0"/>
    <parent link="left_arm_wrist_link"/>
    <child link="left_gripper_base_link"/>
  </joint>
  <!-- Index -->
  <!-- J -->
  <joint name="left_gripper_index_joint" type="revolute">
    <origin rpy="0 0 0" xyz="0.034 0 -0.119"/>
    <axis xyz="-1 0 0"/>
    <limit effort="1.0" lower="0.0" upper="1.570795" velocity="3.14"/>
    <parent link="left_gripper_base_link"/>
    <child link="left_gripper_index_link"/>
  </joint>
  <!-- L -->
  <link name="left_gripper_index_link">
    <inertial>
      <mass value="0.00001"/>
      <origin xyz="0 0 0"/>
      <inertia ixx="1.0" ixy="0.0" ixz="0.0" iyy="1.0" iyz="0.0" izz="1.0"/>
    </inertial>
    <visual>
      <origin rpy="0 0 0" xyz="0 0 0"/>
      <geometry>
        <mesh filename="package://robo_description/meshes/arm/vis/vis_left_index_03.STL" scale="0.001 0.001 0.001"/>
      </geometry>
      <material name="violet"/>
    </visual>
    <collision>
      <origin rpy="0 0 0" xyz="0 0 0"/>
      <geometry>
        <mesh filename="package://robo_description/meshes/arm/col/col_left_index_03.STL" scale="0.001 0.001 0.001"/>
      </geometry>
    </collision>
  </link>
  <!-- Thumb -->
  <!-- J -->
  <joint name="left_gripper_thumb_joint" type="revolute">
    <origin rpy="0 0 0" xyz="0.06 0 -0.0685"/>
    <axis xyz="0 0 -1.0"/>
    <limit effort="1.0" lower="0.0" upper="1.570795" velocity="3.14"/>
    <parent link="left_gripper_base_link"/>
    <child link="left_gripper_thumb_link"/>
  </joint>
  <!-- L -->
  <link name="left_gripper_thumb_link">
    <inertial>
      <mass value="0.00001"/>
      <origin xyz="0 0 0"/>
      <inertia ixx="1.0" ixy="0.0" ixz="0.0" iyy="1.0" iyz="0.0" izz="1.0"/>
    </inertial>
    <visual>
      <origin rpy="0 0 0" xyz="0 0 0"/>
      <geometry>
        <mesh filename="package://robo_description/meshes/arm/vis/vis_left_thumb_03.STL" scale="0.001 0.001 0.001"/>
      </geometry>
      <material name="violet"/>
    </visual>
    <collision>
      <origin rpy="0 0 0" xyz="0 0 0"/>
      <geometry>
        <mesh filename="package://robo_description/meshes/arm/col/col_left_thumb_03.STL" scale="0.001 0.001 0.001"/>
      </geometry>
    </collision>
  </link>
  <!-- Fake gripper link and joint for grasp planning -->
  <!-- J -->
  <joint name="left_gripper_joint" type="fixed">
    <origin rpy="-1.570795 0 0" xyz="0 -0.03 -0.09"/>
    <parent link="left_gripper_base_link"/>
    <child link="left_gripper_link"/>
  </joint>
  <!-- L -->
  <link name="left_gripper_link">
    <visual>
      <origin rpy="0 0 0" xyz="0 0 0"/>
      <geometry>
        <box size="0.005 0.005 0.005"/>
      </geometry>
    </visual>
    <collision>
      <origin rpy="0 0 0" xyz="0 0 0"/>
      <geometry>
        <box size="0.005 0.005 0.005"/>
      </geometry>
    </collision>
  </link>
</robot>

